Workbook

Sheet Attribute_Config
A1: ID | B1: Added in | C1: In D10 | D1: In D20 | E1: In D40 | F1: Attribute | G1: NHANES file | H1: NHANES variable | I1: Native unit | J1: LOINC (NHANES) | K1: PIC LOINC (D10 only) | L1: Semantic group | M1: HPO ID | N1: HPO official anchor | O1: Rule class | P1: Eligibility | Q1: Cohort handling | R1: Mapping provenance | S1: Freeze status | T1: CDC source | U1: LOINC source | V1: HPO source
A2: 1 | B2: D10 | C2: Yes | D2: Yes | E2: Yes | F2: Sodium | G2: BIOPRO_L | H2: LBXSNASI | I2: mmol/L | J2: 2951-2 | K2: 2947-0 | L2: G1 | M2: HP:0003111 | N2: Abnormal circulating electrolyte concentration | O2: Frozen public reference interval/decision rule; see Decision_Rules + Rule_Lookup | P2: PIC 1–17; NHANES adult cohort | Q2: Use PIC base cohort and the fixed NHANES adult cohort; retain item-level missingness; no complete-case filtering | R2: Current manuscript Table 2; preserve unchanged | S2: FROZEN | T2: https://wwwn.cdc.gov/Nchs/Data/Nhanes/Public/2021/DataFiles/BIOPRO_L.htm | U2: https://loinc.org/2951-2 | V2: https://hpo.jax.org/browse/term/HP:0003111
A3: 2 | B3: D10 | C3: Yes | D3: Yes | E3: Yes | F3: Chloride | G3: BIOPRO_L | H3: LBXSCLSI | I3: mmol/L | J3: 2075-0 | K3: 2069-3 | L3: G1 | M3: HP:0003111 | N3: Abnormal circulating electrolyte concentration | O3: Frozen public reference interval/decision rule; see Decision_Rules + Rule_Lookup | P3: PIC 1–17; NHANES adult cohort | Q3: Use PIC base cohort and the fixed NHANES adult cohort; retain item-level missingness; no complete-case filtering | R3: Current manuscript Table 2; preserve unchanged | S3: FROZEN | T3: https://wwwn.cdc.gov/Nchs/Data/Nhanes/Public/2021/DataFiles/BIOPRO_L.htm | U3: https://loinc.org/2075-0 | V3: https://hpo.jax.org/browse/term/HP:0003111
A4: 3 | B4: D10 | C4: Yes | D4: Yes | E4: Yes | F4: Magnesium | G4: BIOPRO_L | H4: LBXMAGN | I4: mg/dL | J4: 19123-9 | K4: 19123-9 | L4: G1 | M4: HP:0003111 | N4: Abnormal circulating electrolyte concentration | O4: Frozen public reference interval/decision rule; see Decision_Rules + Rule_Lookup | P4: PIC 1–17; NHANES adult cohort | Q4: Use PIC base cohort and the fixed NHANES adult cohort; retain item-level missingness; no complete-case filtering | R4: Current manuscript Table 2; preserve unchanged | S4: FROZEN | T4: https://wwwn.cdc.gov/Nchs/Data/Nhanes/Public/2021/DataFiles/BIOPRO_L.htm | U4: https://loinc.org/19123-9 | V4: https://hpo.jax.org/browse/term/HP:0003111
A5: 4 | B5: D10 | C5: Yes | D5: Yes | E5: Yes | F5: Phosphate (phosphorus) | G5: BIOPRO_L | H5: LBXSPH | I5: mg/dL | J5: 2777-1 | K5: 2777-1 | L5: G1 | M5: HP:0003111 | N5: Abnormal circulating electrolyte concentration | O5: Frozen public reference interval/decision rule; see Decision_Rules + Rule_Lookup | P5: PIC 1–17; NHANES adult cohort | Q5: Use PIC base cohort and the fixed NHANES adult cohort; retain item-level missingness; no complete-case filtering | R5: Current manuscript Table 2; preserve unchanged | S5: FROZEN | T5: https://wwwn.cdc.gov/Nchs/Data/Nhanes/Public/2021/DataFiles/BIOPRO_L.htm | U5: https://loinc.org/2777-1 | V5: https://hpo.jax.org/browse/term/HP:0003111
A6: 5 | B6: D10 | C6: Yes | D6: Yes | E6: Yes | F6: Creatinine | G6: BIOPRO_L | H6: LBXSCR | I6: mg/dL | J6: 2160-0 | K6: 2160-0 | L6: G2 | M6: HP:0004364 | N6: Abnormal circulating nitrogen compound concentration | O6: Frozen public reference interval/decision rule; see Decision_Rules + Rule_Lookup | P6: PIC 1–17; NHANES adult cohort | Q6: Use PIC base cohort and the fixed NHANES adult cohort; retain item-level missingness; no complete-case filtering | R6: Current manuscript Table 2; preserve unchanged | S6: FROZEN | T6: https://wwwn.cdc.gov/Nchs/Data/Nhanes/Public/2021/DataFiles/BIOPRO_L.htm | U6: https://loinc.org/2160-0 | V6: https://hpo.jax.org/browse/term/HP:0004364
A7: 6 | B7: D10 | C7: Yes | D7: Yes | E7: Yes | F7: Urea nitrogen (BUN) | G7: BIOPRO_L | H7: LBXSBU | I7: mg/dL | J7: 3094-0 | K7: 3094-0 | L7: G2 | M7: HP:0004364 | N7: Abnormal circulating nitrogen compound concentration | O7: Frozen public reference interval/decision rule; see Decision_Rules + Rule_Lookup | P7: PIC 1–17; NHANES adult cohort | Q7: Use PIC base cohort and the fixed NHANES adult cohort; retain item-level missingness; no complete-case filtering | R7: Current manuscript Table 2; preserve unchanged | S7: FROZEN | T7: https://wwwn.cdc.gov/Nchs/Data/Nhanes/Public/2021/DataFiles/BIOPRO_L.htm | U7: https://loinc.org/3094-0 | V7: https://hpo.jax.org/browse/term/HP:0004364
A8: 7 | B8: D10 | C8: Yes | D8: Yes | E8: Yes | F8: Glucose | G8: BIOPRO_L | H8: LBXSGL | I8: mg/dL | J8: 2345-7 | K8: 2339-0 | L8: G3 | M8: HP:0001939 | N8: Abnormality of metabolism/homeostasis | O8: Frozen public reference interval/decision rule; see Decision_Rules + Rule_Lookup | P8: PIC 1–17; NHANES adult cohort | Q8: Use PIC base cohort and the fixed NHANES adult cohort; retain item-level missingness; no complete-case filtering | R8: Current manuscript Table 2; preserve unchanged | S8: FROZEN | T8: https://wwwn.cdc.gov/Nchs/Data/Nhanes/Public/2021/DataFiles/BIOPRO_L.htm | U8: https://loinc.org/2345-7 | V8: https://hpo.jax.org/browse/term/HP:0001939
A9: 8 | B9: D10 | C9: Yes | D9: Yes | E9: Yes | F9: Albumin | G9: BIOPRO_L | H9: LBXSAL | I9: g/dL | J9: 1751-7 | K9: 1751-7 | L9: G3 | M9: HP:0001939 | N9: Abnormality of metabolism/homeostasis | O9: Frozen public reference interval/decision rule; see Decision_Rules + Rule_Lookup | P9: PIC 1–17; NHANES adult cohort | Q9: Use PIC base cohort and the fixed NHANES adult cohort; retain item-level missingness; no complete-case filtering | R9: Current manuscript Table 2; preserve unchanged | S9: FROZEN | T9: https://wwwn.cdc.gov/Nchs/Data/Nhanes/Public/2021/DataFiles/BIOPRO_L.htm | U9: https://loinc.org/1751-7 | V9: https://hpo.jax.org/browse/term/HP:0001939
A10: 9 | B10: D10 | C10: Yes | D10: Yes | E10: Yes | F10: Hemoglobin | G10: CBC_L | H10: LBXHGB | I10: g/dL | J10: 718-7 | K10: 718-7 | L10: G4 | M10: HP:0001871 | N10: Abnormality of blood and blood-forming tissues | O10: Frozen public reference interval/decision rule; see Decision_Rules + Rule_Lookup | P10: PIC 1–17; NHANES adult cohort | Q10: Use PIC base cohort and the fixed NHANES adult cohort; retain item-level missingness; no complete-case filtering | R10: Current manuscript Table 2; preserve unchanged | S10: FROZEN | T10: https://wwwn.cdc.gov/Nchs/Data/Nhanes/Public/2021/DataFiles/CBC_L.htm | U10: https://loinc.org/718-7 | V10: https://hpo.jax.org/browse/term/HP:0001871
A11: 10 | B11: D10 | C11: Yes | D11: Yes | E11: Yes | F11: Platelet count | G11: CBC_L | H11: LBXPLTSI | I11: 10^3 cells/µL | J11: 777-3 | K11: 777-3 | L11: G4 | M11: HP:0001871 | N11: Abnormality of blood and blood-forming tissues | O11: Frozen public reference interval/decision rule; see Decision_Rules + Rule_Lookup | P11: PIC 1–17; NHANES adult cohort | Q11: Use PIC base cohort and the fixed NHANES adult cohort; retain item-level missingness; no complete-case filtering | R11: Current manuscript Table 2; preserve unchanged | S11: FROZEN | T11: https://wwwn.cdc.gov/Nchs/Data/Nhanes/Public/2021/DataFiles/CBC_L.htm | U11: https://loinc.org/777-3 | V11: https://hpo.jax.org/browse/term/HP:0001871
A12: 11 | B12: D20 | C12: No | D12: Yes | E12: Yes | F12: Potassium | G12: BIOPRO_L | H12: LBXSKSI | I12: mmol/L | J12: 2823-3 | L12: G1 | M12: HP:0003111 | N12: Abnormal circulating electrolyte concentration | O12: Frozen public reference interval/decision rule; see Decision_Rules + Rule_Lookup | P12: NHANES adult cohort | Q12: Use same fixed NHANES adult cohort; retain item-level missingness; no complete-case filtering | R12: Frozen D20/D40 extension design; CDC + LOINC + HPO | S12: FROZEN | T12: https://wwwn.cdc.gov/Nchs/Data/Nhanes/Public/2021/DataFiles/BIOPRO_L.htm | U12: https://loinc.org/2823-3 | V12: https://hpo.jax.org/browse/term/HP:0003111
A13: 12 | B13: D20 | C13: No | D13: Yes | E13: Yes | F13: Bicarbonate | G13: BIOPRO_L | H13: LBXSC3SI | I13: mmol/L | J13: 1963-8 | L13: G1 | M13: HP:0003111 | N13: Abnormal circulating electrolyte concentration | O13: Frozen public reference interval/decision rule; see Decision_Rules + Rule_Lookup | P13: NHANES adult cohort | Q13: Use same fixed NHANES adult cohort; retain item-level missingness; no complete-case filtering | R13: Frozen D20/D40 extension design; CDC + LOINC + HPO | S13: FROZEN | T13: https://wwwn.cdc.gov/Nchs/Data/Nhanes/Public/2021/DataFiles/BIOPRO_L.htm | U13: https://loinc.org/1963-8 | V13: https://hpo.jax.org/browse/term/HP:0003111
A14: 13 | B14: D20 | C14: No | D14: Yes | E14: Yes | F14: Total calcium | G14: BIOPRO_L | H14: LBXSCA | I14: mg/dL | J14: 17861-6 | L14: G1 | M14: HP:0003111 | N14: Abnormal circulating electrolyte concentration | O14: Frozen public reference interval/decision rule; see Decision_Rules + Rule_Lookup | P14: NHANES adult cohort | Q14: Use same fixed NHANES adult cohort; retain item-level missingness; no complete-case filtering | R14: Frozen D20/D40 extension design; CDC + LOINC + HPO | S14: FROZEN | T14: https://wwwn.cdc.gov/Nchs/Data/Nhanes/Public/2021/DataFiles/BIOPRO_L.htm | U14: https://loinc.org/17861-6 | V14: https://hpo.jax.org/browse/term/HP:0003111
A15: 14 | B15: D20 | C15: No | D15: Yes | E15: Yes | F15: Total protein | G15: BIOPRO_L | H15: LBXSTP | I15: g/dL | J15: 2885-2 | L15: G3 | M15: HP:0001939 | N15: Abnormality of metabolism/homeostasis | O15: Frozen public reference interval/decision rule; see Decision_Rules + Rule_Lookup | P15: NHANES adult cohort | Q15: Use same fixed NHANES adult cohort; retain item-level missingness; no complete-case filtering | R15: Frozen D20/D40 extension design; CDC + LOINC + HPO | S15: FROZEN | T15: https://wwwn.cdc.gov/Nchs/Data/Nhanes/Public/2021/DataFiles/BIOPRO_L.htm | U15: https://loinc.org/2885-2 | V15: https://hpo.jax.org/browse/term/HP:0001939
A16: 15 | B16: D20 | C16: No | D16: Yes | E16: Yes | F16: Alanine aminotransferase (ALT) | G16: BIOPRO_L | H16: LBXSATSI | I16: IU/L | J16: 1742-6 | L16: G5 | M16: HP:0012379 | N16: Abnormal circulating enzyme concentration or activity | O16: Frozen public reference interval/decision rule; see Decision_Rules + Rule_Lookup | P16: NHANES adult cohort | Q16: Use same fixed NHANES adult cohort; retain item-level missingness; no complete-case filtering | R16: Frozen D20/D40 extension design; CDC + LOINC + HPO | S16: FROZEN | T16: https://wwwn.cdc.gov/Nchs/Data/Nhanes/Public/2021/DataFiles/BIOPRO_L.htm | U16: https://loinc.org/1742-6 | V16: https://hpo.jax.org/browse/term/HP:0012379
A17: 16 | B17: D20 | C17: No | D17: Yes | E17: Yes | F17: Aspartate aminotransferase (AST) | G17: BIOPRO_L | H17: LBXSASSI | I17: IU/L | J17: 1920-8 | L17: G5 | M17: HP:0012379 | N17: Abnormal circulating enzyme concentration or activity | O17: Frozen public reference interval/decision rule; see Decision_Rules + Rule_Lookup | P17: NHANES adult cohort | Q17: Use same fixed NHANES adult cohort; retain item-level missingness; no complete-case filtering | R17: Frozen D20/D40 extension design; CDC + LOINC + HPO | S17: FROZEN | T17: https://wwwn.cdc.gov/Nchs/Data/Nhanes/Public/2021/DataFiles/BIOPRO_L.htm | U17: https://loinc.org/1920-8 | V17: https://hpo.jax.org/browse/term/HP:0012379
A18: 17 | B18: D20 | C18: No | D18: Yes | E18: Yes | F18: Alkaline phosphatase (ALP) | G18: BIOPRO_L | H18: LBXSAPSI | I18: IU/L | J18: 6768-6 | L18: G5 | M18: HP:0012379 | N18: Abnormal circulating enzyme concentration or activity | O18: Frozen public reference interval/decision rule; see Decision_Rules + Rule_Lookup | P18: NHANES adult cohort | Q18: Use same fixed NHANES adult cohort; retain item-level missingness; no complete-case filtering | R18: Frozen D20/D40 extension design; CDC + LOINC + HPO | S18: FROZEN | T18: https://wwwn.cdc.gov/Nchs/Data/Nhanes/Public/2021/DataFiles/BIOPRO_L.htm | U18: https://loinc.org/6768-6 | V18: https://hpo.jax.org/browse/term/HP:0012379
A19: 18 | B19: D20 | C19: No | D19: Yes | E19: Yes | F19: Gamma-glutamyl transferase (GGT) | G19: BIOPRO_L | H19: LBXSGTSI | I19: IU/L | J19: 2324-2 | L19: G5 | M19: HP:0012379 | N19: Abnormal circulating enzyme concentration or activity | O19: Frozen public reference interval/decision rule; see Decision_Rules + Rule_Lookup | P19: NHANES adult cohort | Q19: Use same fixed NHANES adult cohort; retain item-level missingness; no complete-case filtering | R19: Frozen D20/D40 extension design; CDC + LOINC + HPO | S19: FROZEN | T19: https://wwwn.cdc.gov/Nchs/Data/Nhanes/Public/2021/DataFiles/BIOPRO_L.htm | U19: https://loinc.org/2324-2 | V19: https://hpo.jax.org/browse/term/HP:0012379
A20: 19 | B20: D20 | C20: No | D20: Yes | E20: Yes | F20: Total bilirubin | G20: BIOPRO_L | H20: LBXSTB | I20: mg/dL | J20: 1975-2 | L20: G3 | M20: HP:0001939 | N20: Abnormality of metabolism/homeostasis | O20: Frozen public reference interval/decision rule; see Decision_Rules + Rule_Lookup | P20: NHANES adult cohort | Q20: Use same fixed NHANES adult cohort; retain item-level missingness; no complete-case filtering | R20: Frozen D20/D40 extension design; CDC + LOINC + HPO | S20: FROZEN | T20: https://wwwn.cdc.gov/Nchs/Data/Nhanes/Public/2021/DataFiles/BIOPRO_L.htm | U20: https://loinc.org/1975-2 | V20: https://hpo.jax.org/browse/term/HP:0001939
A21: 20 | B21: D20 | C21: No | D21: Yes | E21: Yes | F21: Uric acid | G21: BIOPRO_L | H21: LBXSUA | I21: mg/dL | J21: 3084-1 | L21: G2 | M21: HP:0004364 | N21: Abnormal circulating nitrogen compound concentration | O21: Frozen public reference interval/decision rule; see Decision_Rules + Rule_Lookup | P21: NHANES adult cohort | Q21: Use same fixed NHANES adult cohort; retain item-level missingness; no complete-case filtering | R21: Frozen D20/D40 extension design; CDC + LOINC + HPO | S21: FROZEN | T21: https://wwwn.cdc.gov/Nchs/Data/Nhanes/Public/2021/DataFiles/BIOPRO_L.htm | U21: https://loinc.org/3084-1 | V21: https://hpo.jax.org/browse/term/HP:0004364
A22: 21 | B22: D40 | C22: No | D22: No | E22: Yes | F22: Creatine kinase (CK/CPK) | G22: BIOPRO_L | H22: LBXSCK | I22: U/L | J22: 2157-6 | L22: G5 | M22: HP:0012379 | N22: Abnormal circulating enzyme concentration or activity | O22: Frozen public reference interval/decision rule; see Decision_Rules + Rule_Lookup | P22: NHANES adult cohort | Q22: Use same fixed NHANES adult cohort; retain item-level missingness; no complete-case filtering | R22: Frozen D20/D40 extension design; CDC + LOINC + HPO | S22: FROZEN | T22: https://wwwn.cdc.gov/Nchs/Data/Nhanes/Public/2021/DataFiles/BIOPRO_L.htm | U22: https://loinc.org/2157-6 | V22: https://hpo.jax.org/browse/term/HP:0012379
A23: 22 | B23: D40 | C23: No | D23: No | E23: Yes | F23: Lactate dehydrogenase (LDH) | G23: BIOPRO_L | H23: LBXSLDSI | I23: U/L | J23: 14804-9 | L23: G5 | M23: HP:0012379 | N23: Abnormal circulating enzyme concentration or activity | O23: Frozen public reference interval/decision rule; see Decision_Rules + Rule_Lookup | P23: NHANES adult cohort | Q23: Use same fixed NHANES adult cohort; retain item-level missingness; no complete-case filtering | R23: Frozen D20/D40 extension design; CDC + LOINC + HPO | S23: FROZEN | T23: https://wwwn.cdc.gov/Nchs/Data/Nhanes/Public/2021/DataFiles/BIOPRO_L.htm | U23: https://loinc.org/14804-9 | V23: https://hpo.jax.org/browse/term/HP:0012379
... A41: 40 | B41: D40 | C41: No | D41: No | E41: Yes | F41: 25-hydroxyvitamin D2 + D3 | G41: VID_L | H41: LBXVIDMS | I41: nmol/L | J41: 68438-1 | L41: G12 | M41: HP:0100511 | N41: Abnormal circulating vitamin D concentration | O41: Frozen public reference interval/decision rule; see Decision_Rules + Rule_Lookup | P41: NHANES adult cohort | Q41: Use same fixed NHANES adult cohort; retain item-level missingness; no complete-case filtering | R41: Frozen D20/D40 extension design; CDC + LOINC + HPO | S41: FROZEN | T41: https://wwwn.cdc.gov/Nchs/Data/Nhanes/Public/2021/DataFiles/VID_L.htm | U41: https://loinc.org/68438-1 | V41: https://hpo.jax.org/browse/term/HP:0100511

Sheet Panel_Summary
A1: Panel | B1: Raw attributes d | C1: Semantic dimensions m_d | D1: Compression d/m_d | E1: Largest group | F1: Group-size profile | G1: Random baseline rule
A2: D10 | B2: =COUNTIF(Attribute_Config!$C$2:$C$41,"Yes") -> 10 | C2: =COUNTIF(Semantic_Groups!$D$2:$D$13,">0") -> 4 | D2: =B2/C2 -> 2.5 | E2: =MAX(Semantic_Groups!$D$2:$D$13) -> 4 | F2: 4,2,2,2 | G2: Reuse fixed 100 structural-control partitions
A3: D20 | B3: =COUNTIF(Attribute_Config!$D$2:$D$41,"Yes") -> 20 | C3: =COUNTIF(Semantic_Groups!$E$2:$E$13,">0") -> 5 | D3: =B3/C3 -> 4 | E3: =MAX(Semantic_Groups!$E$2:$E$13) -> 7 | F3: 7,4,4,3,2 | G3: 100 fixed size-profile-matched partitions
A4: D40 | B4: =COUNTIF(Attribute_Config!$E$2:$E$41,"Yes") -> 40 | C4: =COUNTIF(Semantic_Groups!$F$2:$F$13,">0") -> 12 | D4: =B4/C4 -> 3.3333333 | E4: =MAX(Semantic_Groups!$F$2:$F$13) -> 7 | F4: 7,6,6,5,5,3,2,1,1,1,1,1 | G4: 100 fixed size-profile-matched partitions
A5: Notes | G5: Shared D10 mappings remain unchanged across D20/D40

Sheet Semantic_Groups
A1: Group | B1: HPO ID | C1: HPO official anchor | D1: D10 size | E1: D20 size | F1: D40 size | G1: D10 members | H1: D20 members | I1: D40 members | J1: Freeze status
A2: G1 | B2: HP:0003111 | C2: Abnormal circulating electrolyte concentration | D2: =COUNTIFS(Attribute_Config!$L$2:$L$41,$A2,Attribute_Config!$C$2:$C$41,"Yes") -> 4 | E2: =COUNTIFS(Attribute_Config!$L$2:$L$41,$A2,Attribute_Config!$D$2:$D$41,"Yes") -> 7 | F2: =COUNTIFS(Attribute_Config!$L$2:$L$41,$A2,Attribute_Config!$E$2:$E$41,"Yes") -> 7 | G2: Sodium; Chloride; Magnesium; Phosphate (phosphorus) | H2: Sodium; Chloride; Magnesium; Phosphate (phosphorus); Potassium; Bicarbonate; Total calcium | I2: Sodium; Chloride; Magnesium; Phosphate (phosphorus); Potassium; Bicarbonate; Total calcium | J2: FROZEN
A3: G2 | B3: HP:0004364 | C3: Abnormal circulating nitrogen compound concentration | D3: =COUNTIFS(Attribute_Config!$L$2:$L$41,$A3,Attribute_Config!$C$2:$C$41,"Yes") -> 2 | E3: =COUNTIFS(Attribute_Config!$L$2:$L$41,$A3,Attribute_Config!$D$2:$D$41,"Yes") -> 3 | F3: =COUNTIFS(Attribute_Config!$L$2:$L$41,$A3,Attribute_Config!$E$2:$E$41,"Yes") -> 3 | G3: Creatinine; Urea nitrogen (BUN) | H3: Creatinine; Urea nitrogen (BUN); Uric acid | I3: Creatinine; Urea nitrogen (BUN); Uric acid | J3: FROZEN
A4: G3 | B4: HP:0001939 | C4: Abnormality of metabolism/homeostasis | D4: =COUNTIFS(Attribute_Config!$L$2:$L$41,$A4,Attribute_Config!$C$2:$C$41,"Yes") -> 2 | E4: =COUNTIFS(Attribute_Config!$L$2:$L$41,$A4,Attribute_Config!$D$2:$D$41,"Yes") -> 4 | F4: =COUNTIFS(Attribute_Config!$L$2:$L$41,$A4,Attribute_Config!$E$2:$E$41,"Yes") -> 5 | G4: Glucose; Albumin | H4: Glucose; Albumin; Total protein; Total bilirubin | I4: Glucose; Albumin; Total protein; Total bilirubin; Glycohemoglobin (HbA1c) | J4: FROZEN
A5: G4 | B5: HP:0001871 | C5: Abnormality of blood and blood-forming tissues | D5: =COUNTIFS(Attribute_Config!$L$2:$L$41,$A5,Attribute_Config!$C$2:$C$41,"Yes") -> 2 | E5: =COUNTIFS(Attribute_Config!$L$2:$L$41,$A5,Attribute_Config!$D$2:$D$41,"Yes") -> 2 | F5: =COUNTIFS(Attribute_Config!$L$2:$L$41,$A5,Attribute_Config!$E$2:$E$41,"Yes") -> 2 | G5: Hemoglobin; Platelet count | H5: Hemoglobin; Platelet count | I5: Hemoglobin; Platelet count | J5: FROZEN
A6: G5 | B6: HP:0012379 | C6: Abnormal circulating enzyme concentration or activity | D6: =COUNTIFS(Attribute_Config!$L$2:$L$41,$A6,Attribute_Config!$C$2:$C$41,"Yes") -> 0 | E6: =COUNTIFS(Attribute_Config!$L$2:$L$41,$A6,Attribute_Config!$D$2:$D$41,"Yes") -> 4 | F6: =COUNTIFS(Attribute_Config!$L$2:$L$41,$A6,Attribute_Config!$E$2:$E$41,"Yes") -> 6 | H6: Alanine aminotransferase (ALT); Aspartate aminotransferase (AST); Alkaline phosphatase (ALP); Gamma-glutamyl transferase (GGT) | I6: Alanine aminotransferase (ALT); Aspartate aminotransferase (AST); Alkaline phosphatase (ALP); Gamma-glutamyl transferase (GGT); Creatine kinase (CK/CPK); Lactate dehydrogenase (LDH) | J6: FROZEN
A7: G6 | B7: HP:0003119 | C7: Abnormal circulating lipid concentration | D7: =COUNTIFS(Attribute_Config!$L$2:$L$41,$A7,Attribute_Config!$C$2:$C$41,"Yes") -> 0 | E7: =COUNTIFS(Attribute_Config!$L$2:$L$41,$A7,Attribute_Config!$D$2:$D$41,"Yes") -> 0 | F7: =COUNTIFS(Attribute_Config!$L$2:$L$41,$A7,Attribute_Config!$E$2:$E$41,"Yes") -> 2 | I7: Total cholesterol; HDL cholesterol | J7: FROZEN
A8: G7 | B8: HP:0001881 | C8: Abnormal leukocyte morphology | D8: =COUNTIFS(Attribute_Config!$L$2:$L$41,$A8,Attribute_Config!$C$2:$C$41,"Yes") -> 0 | E8: =COUNTIFS(Attribute_Config!$L$2:$L$41,$A8,Attribute_Config!$D$2:$D$41,"Yes") -> 0 | F8: =COUNTIFS(Attribute_Config!$L$2:$L$41,$A8,Attribute_Config!$E$2:$E$41,"Yes") -> 6 | I8: White blood cell count; Lymphocyte percent; Monocyte percent; Neutrophil percent; Eosinophil percent; Basophil percent | J8: FROZEN
A9: G8 | B9: HP:0001877 | C9: Abnormal erythrocyte morphology | D9: =COUNTIFS(Attribute_Config!$L$2:$L$41,$A9,Attribute_Config!$C$2:$C$41,"Yes") -> 0 | E9: =COUNTIFS(Attribute_Config!$L$2:$L$41,$A9,Attribute_Config!$D$2:$D$41,"Yes") -> 0 | F9: =COUNTIFS(Attribute_Config!$L$2:$L$41,$A9,Attribute_Config!$E$2:$E$41,"Yes") -> 5 | I9: Red blood cell count; Hematocrit; Mean corpuscular volume (MCV); Red cell distribution width (RDW); Nucleated red blood cells (NRBC) | J9: FROZEN
A10: G9 | B10: HP:0011876 | C10: Abnormal platelet volume | D10: =COUNTIFS(Attribute_Config!$L$2:$L$41,$A10,Attribute_Config!$C$2:$C$41,"Yes") -> 0 | E10: =COUNTIFS(Attribute_Config!$L$2:$L$41,$A10,Attribute_Config!$D$2:$D$41,"Yes") -> 0 | F10: =COUNTIFS(Attribute_Config!$L$2:$L$41,$A10,Attribute_Config!$E$2:$E$41,"Yes") -> 1 | I10: Mean platelet volume (MPV) | J10: FROZEN
A11: G10 | B11: HP:0040130 | C11: Abnormal circulating iron concentration | D11: =COUNTIFS(Attribute_Config!$L$2:$L$41,$A11,Attribute_Config!$C$2:$C$41,"Yes") -> 0 | E11: =COUNTIFS(Attribute_Config!$L$2:$L$41,$A11,Attribute_Config!$D$2:$D$41,"Yes") -> 0 | F11: =COUNTIFS(Attribute_Config!$L$2:$L$41,$A11,Attribute_Config!$E$2:$E$41,"Yes") -> 1 | I11: Iron | J11: FROZEN
A12: G11 | B12: HP:0032436 | C12: Abnormal circulating C-reactive protein concentration | D12: =COUNTIFS(Attribute_Config!$L$2:$L$41,$A12,Attribute_Config!$C$2:$C$41,"Yes") -> 0 | E12: =COUNTIFS(Attribute_Config!$L$2:$L$41,$A12,Attribute_Config!$D$2:$D$41,"Yes") -> 0 | F12: =COUNTIFS(Attribute_Config!$L$2:$L$41,$A12,Attribute_Config!$E$2:$E$41,"Yes") -> 1 | I12: High-sensitivity C-reactive protein (hs-CRP) | J12: FROZEN
A13: G12 | B13: HP:0100511 | C13: Abnormal circulating vitamin D concentration | D13: =COUNTIFS(Attribute_Config!$L$2:$L$41,$A13,Attribute_Config!$C$2:$C$41,"Yes") -> 0 | E13: =COUNTIFS(Attribute_Config!$L$2:$L$41,$A13,Attribute_Config!$D$2:$D$41,"Yes") -> 0 | F13: =COUNTIFS(Attribute_Config!$L$2:$L$41,$A13,Attribute_Config!$E$2:$E$41,"Yes") -> 1 | I13: 25-hydroxyvitamin D2 + D3 | J13: FROZEN

Sheet Decision_Rules
A1: ID | B1: Attribute | C1: NHANES variable | D1: Unit | E1: Panel added | F1: Rule type | G1: Context variables | H1: Lower threshold | I1: Upper threshold | J1: Abnormal logic | K1: Source ID | L1: Rule status | M1: Notes | N1: Dataset scope | O1: Frozen normal rule | P1: Source URL
A2: 1 | B2: Sodium | C2: LBXSNASI | D2: mmol/L | E2: D10 | F2: Public reference interval | G2: None (age ≥1 eligibility) | H2: 135 | I2: 145 | J2: x < 135 OR x > 145 | K2: S01 | L2: FROZEN | M2: Shared D10 rule used for PIC and NHANES; do not change after rerun begins. | N2: PIC + NHANES | O2: ≥1y: 135–145 | P2: https://www.mayocliniclabs.com/test-catalog/overview/113630
A3: 2 | B3: Chloride | C3: LBXSCLSI | D3: mmol/L | E3: D10 | F3: Public reference interval | G3: Age | H3: Context-specific | I3: Context-specific | J3: Outside the matched Rule_Lookup interval/decision criterion | K3: S01 | L3: FROZEN | M3: Shared D10 rule used for PIC and NHANES; do not change after rerun begins. | N3: PIC + NHANES | O3: 1–17y: 102–112; ≥18y: 98–107 | P3: https://www.mayocliniclabs.com/test-catalog/overview/113630
A4: 3 | B4: Magnesium | C4: LBXMAGN | D4: mg/dL | E4: D10 | F4: Public reference interval | G4: Age | H4: Context-specific | I4: Context-specific | J4: Outside the matched Rule_Lookup interval/decision criterion | K4: S02 | L4: FROZEN | M4: Shared D10 rule used for PIC and NHANES; do not change after rerun begins. | N4: PIC + NHANES | O4: 1–2y: 1.6–2.7; 3–5y: 1.6–2.6; 6–8y: 1.6–2.5; 9–11y: 1.6–2.4; 12–17y: 1.6–2.3; ≥18y: 1.7–2.3 | P4: https://www.mayocliniclabs.com/test-catalog/overview/8448
A5: 4 | B5: Phosphate (phosphorus) | C5: LBXSPH | D5: mg/dL | E5: D10 | F5: Public reference interval | G5: Age + sex | H5: Context-specific | I5: Context-specific | J5: Outside the matched Rule_Lookup interval/decision criterion | K5: S03 | L5: FROZEN | M5: Shared D10 rule used for PIC and NHANES; do not change after rerun begins. | N5: PIC + NHANES | O5: M 1–4y: 4.3–5.4; M 5–13y: 3.7–5.4; M 14–15y: 3.5–5.3; M 16–17y: 3.1–4.7; M ≥18y: 2.5–4.5; F 1–7y: 4.3–5.4; F 8–13y: 4–5.2; F 14–15y: 3.5–4.9; F 16–17y: 3.1–4.7; F ≥18y: 2.5–4.5 | P5: https://www.mayocliniclabs.com/test-catalog/Overview/8408
A6: 5 | B6: Creatinine | C6: LBXSCR | D6: mg/dL | E6: D10 | F6: Public reference interval | G6: Age + sex | H6: Context-specific | I6: Context-specific | J6: Outside the matched Rule_Lookup interval/decision criterion | K6: S01 | L6: FROZEN | M6: Shared D10 rule used for PIC and NHANES; do not change after rerun begins. | N6: PIC + NHANES | O6: M 1–5y: 0.19–0.49; M 6–10y: 0.26–0.61; M 11–14y: 0.35–0.86; M ≥15y: 0.74–1.35; F 1–5y: 0.19–0.49; F 6–10y: 0.26–0.61; F 11–15y: 0.35–0.86; F ≥16y: 0.59–1.04 | P6: https://www.mayocliniclabs.com/test-catalog/overview/113630
A7: 6 | B7: Urea nitrogen (BUN) | C7: LBXSBU | D7: mg/dL | E7: D10 | F7: Public reference interval | G7: Age + sex | H7: Context-specific | I7: Context-specific | J7: Outside the matched Rule_Lookup interval/decision criterion | K7: S01 | L7: FROZEN | M7: Shared D10 rule used for PIC and NHANES; do not change after rerun begins. | N7: PIC + NHANES | O7: 1–17y: 7–20; M ≥18y: 8–24; F ≥18y: 6–21 | P7: https://www.mayocliniclabs.com/test-catalog/overview/113630
A8: 7 | B8: Glucose | C8: LBXSGL | D8: mg/dL | E8: D10 | F8: Public reference interval | G8: None (age ≥1 eligibility) | H8: 70 | I8: 140 | J8: x < 70 OR x > 140 | K8: S01 | L8: FROZEN | M8: Shared D10 rule used for PIC and NHANES; do not change after rerun begins. Uses non-fasting/random glucose reference interval (70–140 mg/dL), not fasting glucose cutoffs. | N8: PIC + NHANES | O8: ≥1y: 70–140 | P8: https://www.mayocliniclabs.com/test-catalog/overview/113630
A9: 8 | B9: Albumin | C9: LBXSAL | D9: g/dL | E9: D10 | F9: Public reference interval | G9: None (age ≥1 eligibility) | H9: 3.5 | I9: 5.0 | J9: x < 3.5 OR x > 5.0 | K9: S04 | L9: FROZEN | M9: Shared D10 rule used for PIC and NHANES; do not change after rerun begins. | N9: PIC + NHANES | O9: ≥1y: 3.5–5 | P9: https://www.mayocliniclabs.com/test-catalog/overview/113634
A10: 9 | B10: Hemoglobin | C10: LBXHGB | D10: g/dL | E10: D10 | F10: Public reference interval | G10: Age + sex | H10: Context-specific | I10: Context-specific | J10: Outside the matched Rule_Lookup interval/decision criterion | K10: S05 | L10: FROZEN | M10: Shared D10 rule used for PIC and NHANES; do not change after rerun begins. | N10: PIC + NHANES | O10: M 1y: 10.1–12.5; M 2y: 10.2–12.7; M 3–5y: 11.4–14.3; M 6–8y: 11.5–14.3; M 9–10y: 11.8–14.7; M 11–14y: 12.4–15.7; M 15–17y: 13.3–16.9; M ≥18y: 13.2–16.6; F 1–2y: 10.2–12.7; F 3–5y: 11.4–14.3; F 6–8y: 11.5–14.3; F 9–10y: 11.8–14.7; F 11–17y: 11.9–14.8; F ≥18y: 11.6–15 | P10: https://www.mayocliniclabs.com/test-catalog/Overview/801417
A11: 10 | B11: Platelet count | C11: LBXPLTSI | D11: 10^3 cells/µL | E11: D10 | F11: Public reference interval | G11: Age + sex | H11: Context-specific | I11: Context-specific | J11: Outside the matched Rule_Lookup interval/decision criterion | K11: S06 | L11: FROZEN | M11: Shared D10 rule used for PIC and NHANES; do not change after rerun begins. | N11: PIC + NHANES | O11: M 1y: 206–445; M 2y: 202–403; M 3–5y: 187–445; M 6–9y: 187–400; M 10–13y: 177–381; M 14–17y: 139–320; M ≥18y: 135–317; F 1y: 214–459; F 2y: 189–394; F 3–5y: 187–445; F 6–9y: 187–400; F 10–13y: 177–381; F 14–17y: 158–362; F ≥18y: 157–371 | P11: https://www.mayocliniclabs.com/test-catalog/overview/9109
A12: 11 | B12: Potassium | C12: LBXSKSI | D12: mmol/L | E12: D20 | F12: Public reference interval | G12: None (adult cohort) | H12: 3.6 | I12: 5.2 | J12: x < 3.6 OR x > 5.2 | K12: S01 | L12: FROZEN | M12: NHANES adult scalability rule; do not change after rerun begins. | N12: NHANES adults | O12: 3.6–5.2 | P12: https://www.mayocliniclabs.com/test-catalog/overview/113630
A13: 12 | B13: Bicarbonate | C13: LBXSC3SI | D13: mmol/L | E13: D20 | F13: Public reference interval | G13: None (adult cohort) | H13: 22 | I13: 29 | J13: x < 22 OR x > 29 | K13: S01 | L13: FROZEN | M13: NHANES adult scalability rule; do not change after rerun begins. | N13: NHANES adults | O13: 22–29 | P13: https://www.mayocliniclabs.com/test-catalog/overview/113630
... A24: 23 | B24: Iron | C24: LBXSIR | D24: µg/dL | E24: D40 | F24: Public reference interval | G24: Sex | H24: Context-specific | I24: Context-specific | J24: Outside the matched Rule_Lookup interval/decision criterion | K24: S15 | L24: FROZEN | M24: NHANES adult scalability rule; do not change after rerun begins. | N24: NHANES adults | O24: M: 50–150; F: 35–145 | P24: https://www.mayocliniclabs.com/test-catalog/overview/2502
A25: 24 | B25: Total cholesterol | C25: LBXTC | D25: mg/dL | E25: D40 | F25: Clinical decision rule | G25: None (adult cohort) | I25: 200 | J25: x >= 200 | K25: S16 | L25: FROZEN | M25: NHANES adult scalability rule; do not change after rerun begins. | N25: NHANES adults | O25: <200 | P25: https://www.mayocliniclabs.com/test-catalog/Overview/616696
A26: 25 | B26: HDL cholesterol | C26: LBDHDD | D26: mg/dL | E26: D40 | F26: Clinical decision rule | G26: Sex | H26: Context-specific | I26: Context-specific | J26: Outside the matched Rule_Lookup interval/decision criterion | K26: S16 | L26: FROZEN | M26: NHANES adult scalability rule; do not change after rerun begins. | N26: NHANES adults | O26: M: ≥40; F: ≥50 | P26: https://www.mayocliniclabs.com/test-catalog/Overview/616696
A27: 26 | B27: White blood cell count | C27: LBXWBCSI | D27: 10^3 cells/µL | E27: D40 | F27: Public reference interval | G27: Sex | H27: Context-specific | I27: Context-specific | J27: Outside the matched Rule_Lookup interval/decision criterion | K27: S21 | L27: FROZEN | M27: NHANES adult scalability rule; do not change after rerun begins. Uses a prespecified public Beckman Coulter adult whole-blood range as a research categorization rule; not claimed as a locally validated NHANES clinical interval. | N27: NHANES adults | O27: M: 3.6–10.2; F: 3.8–11.8 | P27: https://www.beckmancoulter.com/download/file/wsr-262438/C06947AC?type=pdf
A28: 27 | B28: Lymphocyte percent | C28: LBXLYPCT | D28: % | E28: D40 | F28: Public reference interval | G28: Sex | H28: Context-specific | I28: Context-specific | J28: Outside the matched Rule_Lookup interval/decision criterion | K28: S21 | L28: FROZEN | M28: NHANES adult scalability rule; do not change after rerun begins. Uses a prespecified public Beckman Coulter adult whole-blood range as a research categorization rule; not claimed as a locally validated NHANES clinical interval. | N28: NHANES adults | O28: M: 15.2–43.3; F: 16–45.9 | P28: https://www.beckmancoulter.com/download/file/wsr-262438/C06947AC?type=pdf
A29: 28 | B29: Monocyte percent | C29: LBXMOPCT | D29: % | E29: D40 | F29: Public reference interval | G29: Sex | H29: Context-specific | I29: Context-specific | J29: Outside the matched Rule_Lookup interval/decision criterion | K29: S21 | L29: FROZEN | M29: NHANES adult scalability rule; do not change after rerun begins. Uses a prespecified public Beckman Coulter adult whole-blood range as a research categorization rule; not claimed as a locally validated NHANES clinical interval. | N29: NHANES adults | O29: M: 5.5–13.7; F: 4.3–10.9 | P29: https://www.beckmancoulter.com/download/file/wsr-262438/C06947AC?type=pdf
A30: 29 | B30: Neutrophil percent | C30: LBXNEPCT | D30: % | E30: D40 | F30: Public reference interval | G30: Sex | H30: Context-specific | I30: Context-specific | J30: Outside the matched Rule_Lookup interval/decision criterion | K30: S21 | L30: FROZEN | M30: NHANES adult scalability rule; do not change after rerun begins. Uses a prespecified public Beckman Coulter adult whole-blood range as a research categorization rule; not claimed as a locally validated NHANES clinical interval. | N30: NHANES adults | O30: M: 43.5–73.5; F: 42.7–76.8 | P30: https://www.beckmancoulter.com/download/file/wsr-262438/C06947AC?type=pdf
A31: 30 | B31: Eosinophil percent | C31: LBXEOPCT | D31: % | E31: D40 | F31: Public reference interval | G31: Sex | H31: Context-specific | I31: Context-specific | J31: Outside the matched Rule_Lookup interval/decision criterion | K31: S21 | L31: FROZEN | M31: NHANES adult scalability rule; do not change after rerun begins. Uses a prespecified public Beckman Coulter adult whole-blood range as a research categorization rule; not claimed as a locally validated NHANES clinical interval. | N31: NHANES adults | O31: M: 0.8–8.1; F: 0.5–7 | P31: https://www.beckmancoulter.com/download/file/wsr-262438/C06947AC?type=pdf
A32: 31 | B32: Basophil percent | C32: LBXBAPCT | D32: % | E32: D40 | F32: Public reference interval | G32: Sex | H32: Context-specific | I32: Context-specific | J32: Outside the matched Rule_Lookup interval/decision criterion | K32: S21 | L32: FROZEN | M32: NHANES adult scalability rule; do not change after rerun begins. Uses a prespecified public Beckman Coulter adult whole-blood range as a research categorization rule; not claimed as a locally validated NHANES clinical interval. | N32: NHANES adults | O32: M: 0.2–1.5; F: 0.2–1.3 | P32: https://www.beckmancoulter.com/download/file/wsr-262438/C06947AC?type=pdf
A33: 32 | B33: Red blood cell count | C33: LBXRBCSI | D33: 10^6 cells/µL | E33: D40 | F33: Public reference interval | G33: Sex | H33: Context-specific | I33: Context-specific | J33: Outside the matched Rule_Lookup interval/decision criterion | K33: S21 | L33: FROZEN | M33: NHANES adult scalability rule; do not change after rerun begins. Uses a prespecified public Beckman Coulter adult whole-blood range as a research categorization rule; not claimed as a locally validated NHANES clinical interval. | N33: NHANES adults | O33: M: 4.06–5.63; F: 3.63–4.92 | P33: https://www.beckmancoulter.com/download/file/wsr-262438/C06947AC?type=pdf
A34: 33 | B34: Hematocrit | C34: LBXHCT | D34: % | E34: D40 | F34: Public reference interval | G34: Sex | H34: Context-specific | I34: Context-specific | J34: Outside the matched Rule_Lookup interval/decision criterion | K34: S21 | L34: FROZEN | M34: NHANES adult scalability rule; do not change after rerun begins. Uses a prespecified public Beckman Coulter adult whole-blood range as a research categorization rule; not claimed as a locally validated NHANES clinical interval. | N34: NHANES adults | O34: M: 36.7–47.1; F: 31.2–41.9 | P34: https://www.beckmancoulter.com/download/file/wsr-262438/C06947AC?type=pdf
A35: 34 | B35: Mean corpuscular volume (MCV) | C35: LBXMCVSI | D35: fL | E35: D40 | F35: Public reference interval | G35: Sex | H35: Context-specific | I35: Context-specific | J35: Outside the matched Rule_Lookup interval/decision criterion | K35: S21 | L35: FROZEN | M35: NHANES adult scalability rule; do not change after rerun begins. Uses a prespecified public Beckman Coulter adult whole-blood range as a research categorization rule; not claimed as a locally validated NHANES clinical interval. | N35: NHANES adults | O35: M: 73–96.2; F: 75.5–95.3 | P35: https://www.beckmancoulter.com/download/file/wsr-262438/C06947AC?type=pdf
A36: 35 | B36: Red cell distribution width (RDW) | C36: LBXRDW | D36: % | E36: D40 | F36: Public reference interval | G36: Sex | H36: Context-specific | I36: Context-specific | J36: Outside the matched Rule_Lookup interval/decision criterion | K36: S21 | L36: FROZEN | M36: NHANES adult scalability rule; do not change after rerun begins. Uses a prespecified public Beckman Coulter adult whole-blood range as a research categorization rule; not claimed as a locally validated NHANES clinical interval. | N36: NHANES adults | O36: M: 12.1–16.2; F: 12.3–17.7 | P36: https://www.beckmancoulter.com/download/file/wsr-262438/C06947AC?type=pdf
A37: 36 | B37: Nucleated red blood cells (NRBC) | C37: LBXNRBC | D37: /100 WBC | E37: D40 | F37: Public reference interval | G37: Sex | H37: Context-specific | I37: Context-specific | J37: Outside the matched Rule_Lookup interval/decision criterion | K37: S21 | L37: FROZEN | M37: NHANES adult scalability rule; do not change after rerun begins. Uses a prespecified public Beckman Coulter adult whole-blood range as a research categorization rule; not claimed as a locally validated NHANES clinical interval. | N37: NHANES adults | O37: M: 0–0.6; F: 0–0.3 | P37: https://www.beckmancoulter.com/download/file/wsr-262438/C06947AC?type=pdf
A38: 37 | B38: Mean platelet volume (MPV) | C38: LBXMPSI | D38: fL | E38: D40 | F38: Public reference interval | G38: Sex | H38: Context-specific | I38: Context-specific | J38: Outside the matched Rule_Lookup interval/decision criterion | K38: S21 | L38: FROZEN | M38: NHANES adult scalability rule; do not change after rerun begins. Uses a prespecified public Beckman Coulter adult whole-blood range as a research categorization rule; not claimed as a locally validated NHANES clinical interval. | N38: NHANES adults | O38: M: 7.4–11.4; F: 7.9–10.8 | P38: https://www.beckmancoulter.com/download/file/wsr-262438/C06947AC?type=pdf
A39: 38 | B39: Glycohemoglobin (HbA1c) | C39: LBXGH | D39: % | E39: D40 | F39: Clinical decision rule | G39: None (adult cohort) | I39: 5.7 | J39: x >= 5.7 | K39: S17 | L39: FROZEN | M39: NHANES adult scalability rule; do not change after rerun begins. Prediabetes and diabetes ranges are both collapsed to the abnormal state. | N39: NHANES adults | O39: <5.7 | P39: https://www.cdc.gov/diabetes/diabetes-testing/prediabetes-a1c-test.html
A40: 39 | B40: High-sensitivity C-reactive protein (hs-CRP) | C40: LBXHSCRP | D40: mg/L | E40: D40 | F40: Clinical decision rule | G40: None (adult cohort) | I40: 2.0 | J40: x >= 2.0 | K40: S18 | L40: FROZEN | M40: NHANES adult scalability rule; do not change after rerun begins. Risk-oriented hs-CRP decision rule, not a diagnostic inflammation cutoff. | N40: NHANES adults | O40: <2 | P40: https://www.mayocliniclabs.com/test-catalog/Overview/800024
A41: 40 | B41: 25-hydroxyvitamin D2 + D3 | C41: LBXVIDMS | D41: nmol/L | E41: D40 | F41: Clinical decision rule | G41: None (adult cohort) | H41: 50 | I41: 125 | J41: x < 50 OR x > 125 | K41: S19 | L41: FROZEN | M41: NHANES adult scalability rule; do not change after rerun begins. 50–125 nmol/L is the frozen adequate band; outside this band is abnormal. | N41: NHANES adults | O41: 50–125 | P41: https://ods.od.nih.gov/factsheets/VitaminD-HealthProfessional/

Sheet Excluded_Candidates
A1: Candidate | B1: NHANES source | C1: Reason excluded | D1: Decision
A2: Triglycerides (TRIGLY_L LBXTLG) | B2: TRIGLY_L | C2: Morning-session fasting subsample; violates the no-special-subsample criterion | D2: EXCLUDE
A3: LDL cholesterol (all released LDL variables) | B3: TRIGLY_L | C3: Calculated from total cholesterol, triglycerides, and HDL; not directly measured | D3: EXCLUDE
A4: BIOPRO triglycerides (LBXSTR) | B4: BIOPRO_L | C4: CDC states reference-method triglyceride result should generally be used; retained BIOPRO value is not recommended routinely | D4: EXCLUDE
A5: BIOPRO total cholesterol (LBXSCH) | B5: BIOPRO_L | C5: CDC recommends the reference-method TCHOL_L result instead; use LBXTC | D5: EXCLUDE
A6: Globulin (LBXSGB) | B6: BIOPRO_L | C6: Calculated from total protein minus albumin | D6: EXCLUDE
A7: Calculated osmolality (LBXSOSSI) | B7: BIOPRO_L | C7: Calculated from sodium, glucose, and BUN | D7: EXCLUDE
A8: CBC absolute differential counts (LBDLYMNO/LBDMONO/LBDNENO/LBDEONO/LBDBANO) | B8: CBC_L | C8: CDC explicitly lists these five variables as derived from WBC × differential percentage | D8: EXCLUDE
A9: MCH / MCHC | B9: CBC_L | C9: Strong algebraic redundancy with RBC/HGB/HCT/MCV; omitted to avoid unnecessary deterministic structure | D9: EXCLUDE
A10: Ferritin / transferrin receptor | B10: FERTIN_L / TFR_L | C10: Restricted target population in this cycle; not suitable for the common fixed-cohort expansion | D10: EXCLUDE

Sheet Sources
A1: Source type | B1: Resource | C1: URL | D1: Use in configuration
A2: Manuscript | B2: Current 16-page BDCC draft | C2: Source file: 38062397-20ca-4559-ace6-dd403e8785d3.pdf | D2: Base D10 mapping and scalability criteria
A3: CDC NHANES | B3: BIOPRO_L | C3: https://wwwn.cdc.gov/Nchs/Data/Nhanes/Public/2021/DataFiles/BIOPRO_L.htm | D3: General biochemistry variables; eligibility; direct/derived notes
A4: CDC NHANES | B4: CBC_L | C4: https://wwwn.cdc.gov/Nchs/Data/Nhanes/Public/2021/DataFiles/CBC_L.htm | D4: CBC variables; eligibility; derived absolute differential counts
A5: CDC NHANES | B5: TCHOL_L | C5: https://wwwn.cdc.gov/Nchs/Data/Nhanes/Public/2021/DataFiles/TCHOL_L.htm | D5: Direct total cholesterol; preferred over BIOPRO total cholesterol
A6: CDC NHANES | B6: HDL_L | C6: https://wwwn.cdc.gov/Nchs/Data/Nhanes/Public/2021/DataFiles/HDL_L.htm | D6: Direct HDL cholesterol
A7: CDC NHANES | B7: GHB_L | C7: https://wwwn.cdc.gov/Nchs/Data/Nhanes/Public/2021/DataFiles/GHB_L.htm | D7: HbA1c / glycohemoglobin
A8: CDC NHANES | B8: HSCRP_L | C8: https://wwwn.cdc.gov/Nchs/Data/Nhanes/Public/2021/DataFiles/HSCRP_L.htm | D8: High-sensitivity CRP
A9: CDC NHANES | B9: VID_L | C9: https://wwwn.cdc.gov/Nchs/Data/Nhanes/Public/2021/DataFiles/VID_L.htm | D9: 25-hydroxyvitamin D2 + D3
A10: LOINC | B10: LOINC term pages | C10: https://loinc.org/ | D10: Standardized observation identifiers
A11: HPO | B11: Human Phenotype Ontology browser | C11: https://hpo.jax.org/ | D11: Semantic anchor identifiers and official names
A12: Decision-rule provenance | B12: See Rule_Sources sheet | C12: Rule_Sources | D12: Numerical threshold/decision-rule sources for the frozen final configuration

Sheet Read_Me
A1: KGR-LDP D10/D20/D40 Attribute + Decision-Rule Configuration — FINAL FREEZE
A2: Freeze date | B2: 2026-09-06
A3: Freeze scope | B3: Attribute panels, NHANES variable IDs, units, LOINC/HPO mappings, semantic groups, D10/D20/D40 nesting, and all numerical normal/abnormal rules in Rule_Lookup.
A4: D10 | B4: d=10, m10=4, compression=2.50. D10 rules are shared across PIC and NHANES and include age/sex stratification where required.
A5: D20 | B5: d=20, m20=5, compression=4.00. Added attributes 11–20; D20/D40 threshold rules apply to the fixed NHANES adult cohort.
A6: D40 | B6: d=40, m40=12, compression=3.33. Added attributes 21–40.
A7: Source of truth | B7: Rule_Lookup is the executable threshold table. Decision_Rules is the human-readable summary. Rule_Sources stores the public provenance URLs.
A8: State assignment | B8: If the laboratory value is missing, set attribute state to NA. If observed, select exactly one matching Rule_Lookup row by attribute + age + sex, then assign normal/abnormal from that row.
A9: Context check | B9: Age and sex are local context variables only when a rule requires them. If a required context field is unavailable or no rule matches, STOP and flag the record/configuration; do not silently default to normal or abnormal.
A10: Boundary handling | B10: Lower/upper inclusivity is explicitly stored in Rule_Lookup. Reference-interval endpoints are inclusive unless specified otherwise. Decision rules such as total cholesterol, HbA1c and hs-CRP use the exact inequalities shown.
A11: Fixed cohort rule | B11: Use the same NHANES adult analysis cohort for D10/D20/D40; retain item-level missingness; no complete-case filtering.
A12: Random control rule | B12: Reuse the D10 fixed random partitions from Section 3.1; generate separate fixed size-profile-matched sets for D20 and D40.
A13: Clinical interpretation | B13: These thresholds are frozen algorithmic categorization rules for reproducible research. They are not patient-specific diagnostic recommendations and are not locally validated clinical reference intervals.
... A15: Status | B15: ATTRIBUTE CONFIGURATION: FROZEN | DECISION RULES: FROZEN | READY FOR FINAL RERUN

Sheet Rule_Lookup
A1: Rule key | B1: Attribute ID | C1: Attribute | D1: NHANES variable | E1: Unit | F1: Panel | G1: Dataset scope | H1: Sex | I1: Age min (yr, inclusive) | J1: Age max (yr, exclusive) | K1: Lower | L1: Lower inclusive | M1: Upper | N1: Upper inclusive | O1: Normal rule | P1: Abnormal rule | Q1: Source ID | R1: Source URL | S1: Implementation note
A2: A01_Any_1_INF | B2: 1 | C2: Sodium | D2: LBXSNASI | E2: mmol/L | F2: D10 | G2: PIC + NHANES | H2: Any | I2: 1 | K2: 135 | L2: TRUE | M2: 145 | N2: TRUE | O2: x >= 135 AND x <= 145 | P2: x < 135 OR x > 145 | Q2: S01 | R2: https://www.mayocliniclabs.com/test-catalog/overview/113630 | S2: Public reference interval; age >=1 year.
A3: A02_Any_1_18 | B3: 2 | C3: Chloride | D3: LBXSCLSI | E3: mmol/L | F3: D10 | G3: PIC + NHANES | H3: Any | I3: 1 | J3: 18 | K3: 102 | L3: TRUE | M3: 112 | N3: TRUE | O3: x >= 102 AND x <= 112 | P3: x < 102 OR x > 112 | Q3: S01 | R3: https://www.mayocliniclabs.com/test-catalog/overview/113630
A4: A02_Any_18_INF | B4: 2 | C4: Chloride | D4: LBXSCLSI | E4: mmol/L | F4: D10 | G4: PIC + NHANES | H4: Any | I4: 18 | K4: 98 | L4: TRUE | M4: 107 | N4: TRUE | O4: x >= 98 AND x <= 107 | P4: x < 98 OR x > 107 | Q4: S01 | R4: https://www.mayocliniclabs.com/test-catalog/overview/113630
A5: A03_Any_1_3 | B5: 3 | C5: Magnesium | D5: LBXMAGN | E5: mg/dL | F5: D10 | G5: PIC + NHANES | H5: Any | I5: 1 | J5: 3 | K5: 1.6 | L5: TRUE | M5: 2.7 | N5: TRUE | O5: x >= 1.6 AND x <= 2.7 | P5: x < 1.6 OR x > 2.7 | Q5: S02 | R5: https://www.mayocliniclabs.com/test-catalog/overview/8448
A6: A03_Any_3_6 | B6: 3 | C6: Magnesium | D6: LBXMAGN | E6: mg/dL | F6: D10 | G6: PIC + NHANES | H6: Any | I6: 3 | J6: 6 | K6: 1.6 | L6: TRUE | M6: 2.6 | N6: TRUE | O6: x >= 1.6 AND x <= 2.6 | P6: x < 1.6 OR x > 2.6 | Q6: S02 | R6: https://www.mayocliniclabs.com/test-catalog/overview/8448
A7: A03_Any_6_9 | B7: 3 | C7: Magnesium | D7: LBXMAGN | E7: mg/dL | F7: D10 | G7: PIC + NHANES | H7: Any | I7: 6 | J7: 9 | K7: 1.6 | L7: TRUE | M7: 2.5 | N7: TRUE | O7: x >= 1.6 AND x <= 2.5 | P7: x < 1.6 OR x > 2.5 | Q7: S02 | R7: https://www.mayocliniclabs.com/test-catalog/overview/8448
A8: A03_Any_9_12 | B8: 3 | C8: Magnesium | D8: LBXMAGN | E8: mg/dL | F8: D10 | G8: PIC + NHANES | H8: Any | I8: 9 | J8: 12 | K8: 1.6 | L8: TRUE | M8: 2.4 | N8: TRUE | O8: x >= 1.6 AND x <= 2.4 | P8: x < 1.6 OR x > 2.4 | Q8: S02 | R8: https://www.mayocliniclabs.com/test-catalog/overview/8448
A9: A03_Any_12_18 | B9: 3 | C9: Magnesium | D9: LBXMAGN | E9: mg/dL | F9: D10 | G9: PIC + NHANES | H9: Any | I9: 12 | J9: 18 | K9: 1.6 | L9: TRUE | M9: 2.3 | N9: TRUE | O9: x >= 1.6 AND x <= 2.3 | P9: x < 1.6 OR x > 2.3 | Q9: S02 | R9: https://www.mayocliniclabs.com/test-catalog/overview/8448
A10: A03_Any_18_INF | B10: 3 | C10: Magnesium | D10: LBXMAGN | E10: mg/dL | F10: D10 | G10: PIC + NHANES | H10: Any | I10: 18 | K10: 1.7 | L10: TRUE | M10: 2.3 | N10: TRUE | O10: x >= 1.7 AND x <= 2.3 | P10: x < 1.7 OR x > 2.3 | Q10: S02 | R10: https://www.mayocliniclabs.com/test-catalog/overview/8448
A11: A04_Male_1_5 | B11: 4 | C11: Phosphate (phosphorus) | D11: LBXSPH | E11: mg/dL | F11: D10 | G11: PIC + NHANES | H11: Male | I11: 1 | J11: 5 | K11: 4.3 | L11: TRUE | M11: 5.4 | N11: TRUE | O11: x >= 4.3 AND x <= 5.4 | P11: x < 4.3 OR x > 5.4 | Q11: S03 | R11: https://www.mayocliniclabs.com/test-catalog/Overview/8408
A12: A04_Male_5_14 | B12: 4 | C12: Phosphate (phosphorus) | D12: LBXSPH | E12: mg/dL | F12: D10 | G12: PIC + NHANES | H12: Male | I12: 5 | J12: 14 | K12: 3.7 | L12: TRUE | M12: 5.4 | N12: TRUE | O12: x >= 3.7 AND x <= 5.4 | P12: x < 3.7 OR x > 5.4 | Q12: S03 | R12: https://www.mayocliniclabs.com/test-catalog/Overview/8408
A13: A04_Male_14_16 | B13: 4 | C13: Phosphate (phosphorus) | D13: LBXSPH | E13: mg/dL | F13: D10 | G13: PIC + NHANES | H13: Male | I13: 14 | J13: 16 | K13: 3.5 | L13: TRUE | M13: 5.3 | N13: TRUE | O13: x >= 3.5 AND x <= 5.3 | P13: x < 3.5 OR x > 5.3 | Q13: S03 | R13: https://www.mayocliniclabs.com/test-catalog/Overview/8408
A14: A04_Male_16_18 | B14: 4 | C14: Phosphate (phosphorus) | D14: LBXSPH | E14: mg/dL | F14: D10 | G14: PIC + NHANES | H14: Male | I14: 16 | J14: 18 | K14: 3.1 | L14: TRUE | M14: 4.7 | N14: TRUE | O14: x >= 3.1 AND x <= 4.7 | P14: x < 3.1 OR x > 4.7 | Q14: S03 | R14: https://www.mayocliniclabs.com/test-catalog/Overview/8408
A15: A04_Male_18_INF | B15: 4 | C15: Phosphate (phosphorus) | D15: LBXSPH | E15: mg/dL | F15: D10 | G15: PIC + NHANES | H15: Male | I15: 18 | K15: 2.5 | L15: TRUE | M15: 4.5 | N15: TRUE | O15: x >= 2.5 AND x <= 4.5 | P15: x < 2.5 OR x > 4.5 | Q15: S03 | R15: https://www.mayocliniclabs.com/test-catalog/Overview/8408
A16: A04_Female_1_8 | B16: 4 | C16: Phosphate (phosphorus) | D16: LBXSPH | E16: mg/dL | F16: D10 | G16: PIC + NHANES | H16: Female | I16: 1 | J16: 8 | K16: 4.3 | L16: TRUE | M16: 5.4 | N16: TRUE | O16: x >= 4.3 AND x <= 5.4 | P16: x < 4.3 OR x > 5.4 | Q16: S03 | R16: https://www.mayocliniclabs.com/test-catalog/Overview/8408
A17: A04_Female_8_14 | B17: 4 | C17: Phosphate (phosphorus) | D17: LBXSPH | E17: mg/dL | F17: D10 | G17: PIC + NHANES | H17: Female | I17: 8 | J17: 14 | K17: 4 | L17: TRUE | M17: 5.2 | N17: TRUE | O17: x >= 4.0 AND x <= 5.2 | P17: x < 4.0 OR x > 5.2 | Q17: S03 | R17: https://www.mayocliniclabs.com/test-catalog/Overview/8408
A18: A04_Female_14_16 | B18: 4 | C18: Phosphate (phosphorus) | D18: LBXSPH | E18: mg/dL | F18: D10 | G18: PIC + NHANES | H18: Female | I18: 14 | J18: 16 | K18: 3.5 | L18: TRUE | M18: 4.9 | N18: TRUE | O18: x >= 3.5 AND x <= 4.9 | P18: x < 3.5 OR x > 4.9 | Q18: S03 | R18: https://www.mayocliniclabs.com/test-catalog/Overview/8408
A19: A04_Female_16_18 | B19: 4 | C19: Phosphate (phosphorus) | D19: LBXSPH | E19: mg/dL | F19: D10 | G19: PIC + NHANES | H19: Female | I19: 16 | J19: 18 | K19: 3.1 | L19: TRUE | M19: 4.7 | N19: TRUE | O19: x >= 3.1 AND x <= 4.7 | P19: x < 3.1 OR x > 4.7 | Q19: S03 | R19: https://www.mayocliniclabs.com/test-catalog/Overview/8408
A20: A04_Female_18_INF | B20: 4 | C20: Phosphate (phosphorus) | D20: LBXSPH | E20: mg/dL | F20: D10 | G20: PIC + NHANES | H20: Female | I20: 18 | K20: 2.5 | L20: TRUE | M20: 4.5 | N20: TRUE | O20: x >= 2.5 AND x <= 4.5 | P20: x < 2.5 OR x > 4.5 | Q20: S03 | R20: https://www.mayocliniclabs.com/test-catalog/Overview/8408
A21: A05_Male_1_6 | B21: 5 | C21: Creatinine | D21: LBXSCR | E21: mg/dL | F21: D10 | G21: PIC + NHANES | H21: Male | I21: 1 | J21: 6 | K21: 0.19 | L21: TRUE | M21: 0.49 | N21: TRUE | O21: x >= 0.19 AND x <= 0.49 | P21: x < 0.19 OR x > 0.49 | Q21: S01 | R21: https://www.mayocliniclabs.com/test-catalog/overview/113630
A22: A05_Male_6_11 | B22: 5 | C22: Creatinine | D22: LBXSCR | E22: mg/dL | F22: D10 | G22: PIC + NHANES | H22: Male | I22: 6 | J22: 11 | K22: 0.26 | L22: TRUE | M22: 0.61 | N22: TRUE | O22: x >= 0.26 AND x <= 0.61 | P22: x < 0.26 OR x > 0.61 | Q22: S01 | R22: https://www.mayocliniclabs.com/test-catalog/overview/113630
A23: A05_Male_11_15 | B23: 5 | C23: Creatinine | D23: LBXSCR | E23: mg/dL | F23: D10 | G23: PIC + NHANES | H23: Male | I23: 11 | J23: 15 | K23: 0.35 | L23: TRUE | M23: 0.86 | N23: TRUE | O23: x >= 0.35 AND x <= 0.86 | P23: x < 0.35 OR x > 0.86 | Q23: S01 | R23: https://www.mayocliniclabs.com/test-catalog/overview/113630
A24: A05_Male_15_INF | B24: 5 | C24: Creatinine | D24: LBXSCR | E24: mg/dL | F24: D10 | G24: PIC + NHANES | H24: Male | I24: 15 | K24: 0.74 | L24: TRUE | M24: 1.35 | N24: TRUE | O24: x >= 0.74 AND x <= 1.35 | P24: x < 0.74 OR x > 1.35 | Q24: S01 | R24: https://www.mayocliniclabs.com/test-catalog/overview/113630
A25: A05_Female_1_6 | B25: 5 | C25: Creatinine | D25: LBXSCR | E25: mg/dL | F25: D10 | G25: PIC + NHANES | H25: Female | I25: 1 | J25: 6 | K25: 0.19 | L25: TRUE | M25: 0.49 | N25: TRUE | O25: x >= 0.19 AND x <= 0.49 | P25: x < 0.19 OR x > 0.49 | Q25: S01 | R25: https://www.mayocliniclabs.com/test-catalog/overview/113630
A26: A05_Female_6_11 | B26: 5 | C26: Creatinine | D26: LBXSCR | E26: mg/dL | F26: D10 | G26: PIC + NHANES | H26: Female | I26: 6 | J26: 11 | K26: 0.26 | L26: TRUE | M26: 0.61 | N26: TRUE | O26: x >= 0.26 AND x <= 0.61 | P26: x < 0.26 OR x > 0.61 | Q26: S01 | R26: https://www.mayocliniclabs.com/test-catalog/overview/113630
A27: A05_Female_11_16 | B27: 5 | C27: Creatinine | D27: LBXSCR | E27: mg/dL | F27: D10 | G27: PIC + NHANES | H27: Female | I27: 11 | J27: 16 | K27: 0.35 | L27: TRUE | M27: 0.86 | N27: TRUE | O27: x >= 0.35 AND x <= 0.86 | P27: x < 0.35 OR x > 0.86 | Q27: S01 | R27: https://www.mayocliniclabs.com/test-catalog/overview/113630
A28: A05_Female_16_INF | B28: 5 | C28: Creatinine | D28: LBXSCR | E28: mg/dL | F28: D10 | G28: PIC + NHANES | H28: Female | I28: 16 | K28: 0.59 | L28: TRUE | M28: 1.04 | N28: TRUE | O28: x >= 0.59 AND x <= 1.04 | P28: x < 0.59 OR x > 1.04 | Q28: S01 | R28: https://www.mayocliniclabs.com/test-catalog/overview/113630
A29: A06_Any_1_18 | B29: 6 | C29: Urea nitrogen (BUN) | D29: LBXSBU | E29: mg/dL | F29: D10 | G29: PIC + NHANES | H29: Any | I29: 1 | J29: 18 | K29: 7 | L29: TRUE | M29: 20 | N29: TRUE | O29: x >= 7 AND x <= 20 | P29: x < 7 OR x > 20 | Q29: S01 | R29: https://www.mayocliniclabs.com/test-catalog/overview/113630
A30: A06_Male_18_INF | B30: 6 | C30: Urea nitrogen (BUN) | D30: LBXSBU | E30: mg/dL | F30: D10 | G30: PIC + NHANES | H30: Male | I30: 18 | K30: 8 | L30: TRUE | M30: 24 | N30: TRUE | O30: x >= 8 AND x <= 24 | P30: x < 8 OR x > 24 | Q30: S01 | R30: https://www.mayocliniclabs.com/test-catalog/overview/113630
A31: A06_Female_18_INF | B31: 6 | C31: Urea nitrogen (BUN) | D31: LBXSBU | E31: mg/dL | F31: D10 | G31: PIC + NHANES | H31: Female | I31: 18 | K31: 6 | L31: TRUE | M31: 21 | N31: TRUE | O31: x >= 6 AND x <= 21 | P31: x < 6 OR x > 21 | Q31: S01 | R31: https://www.mayocliniclabs.com/test-catalog/overview/113630
A32: A07_Any_1_INF | B32: 7 | C32: Glucose | D32: LBXSGL | E32: mg/dL | F32: D10 | G32: PIC + NHANES | H32: Any | I32: 1 | K32: 70 | L32: TRUE | M32: 140 | N32: TRUE | O32: x >= 70 AND x <= 140 | P32: x < 70 OR x > 140 | Q32: S01 | R32: https://www.mayocliniclabs.com/test-catalog/overview/113630 | S32: Random/non-fasting serum glucose reference interval; do not substitute fasting thresholds.
A33: A08_Any_1_INF | B33: 8 | C33: Albumin | D33: LBXSAL | E33: g/dL | F33: D10 | G33: PIC + NHANES | H33: Any | I33: 1 | K33: 3.5 | L33: TRUE | M33: 5 | N33: TRUE | O33: x >= 3.5 AND x <= 5.0 | P33: x < 3.5 OR x > 5.0 | Q33: S04 | R33: https://www.mayocliniclabs.com/test-catalog/overview/113634
A34: A09_Male_1_2 | B34: 9 | C34: Hemoglobin | D34: LBXHGB | E34: g/dL | F34: D10 | G34: PIC + NHANES | H34: Male | I34: 1 | J34: 2 | K34: 10.1 | L34: TRUE | M34: 12.5 | N34: TRUE | O34: x >= 10.1 AND x <= 12.5 | P34: x < 10.1 OR x > 12.5 | Q34: S05 | R34: https://www.mayocliniclabs.com/test-catalog/Overview/801417
A35: A09_Male_2_3 | B35: 9 | C35: Hemoglobin | D35: LBXHGB | E35: g/dL | F35: D10 | G35: PIC + NHANES | H35: Male | I35: 2 | J35: 3 | K35: 10.2 | L35: TRUE | M35: 12.7 | N35: TRUE | O35: x >= 10.2 AND x <= 12.7 | P35: x < 10.2 OR x > 12.7 | Q35: S05 | R35: https://www.mayocliniclabs.com/test-catalog/Overview/801417
A36: A09_Male_3_6 | B36: 9 | C36: Hemoglobin | D36: LBXHGB | E36: g/dL | F36: D10 | G36: PIC + NHANES | H36: Male | I36: 3 | J36: 6 | K36: 11.4 | L36: TRUE | M36: 14.3 | N36: TRUE | O36: x >= 11.4 AND x <= 14.3 | P36: x < 11.4 OR x > 14.3 | Q36: S05 | R36: https://www.mayocliniclabs.com/test-catalog/Overview/801417
A37: A09_Male_6_9 | B37: 9 | C37: Hemoglobin | D37: LBXHGB | E37: g/dL | F37: D10 | G37: PIC + NHANES | H37: Male | I37: 6 | J37: 9 | K37: 11.5 | L37: TRUE | M37: 14.3 | N37: TRUE | O37: x >= 11.5 AND x <= 14.3 | P37: x < 11.5 OR x > 14.3 | Q37: S05 | R37: https://www.mayocliniclabs.com/test-catalog/Overview/801417
A38: A09_Male_9_11 | B38: 9 | C38: Hemoglobin | D38: LBXHGB | E38: g/dL | F38: D10 | G38: PIC + NHANES | H38: Male | I38: 9 | J38: 11 | K38: 11.8 | L38: TRUE | M38: 14.7 | N38: TRUE | O38: x >= 11.8 AND x <= 14.7 | P38: x < 11.8 OR x > 14.7 | Q38: S05 | R38: https://www.mayocliniclabs.com/test-catalog/Overview/801417
A39: A09_Male_11_15 | B39: 9 | C39: Hemoglobin | D39: LBXHGB | E39: g/dL | F39: D10 | G39: PIC + NHANES | H39: Male | I39: 11 | J39: 15 | K39: 12.4 | L39: TRUE | M39: 15.7 | N39: TRUE | O39: x >= 12.4 AND x <= 15.7 | P39: x < 12.4 OR x > 15.7 | Q39: S05 | R39: https://www.mayocliniclabs.com/test-catalog/Overview/801417
A40: A09_Male_15_18 | B40: 9 | C40: Hemoglobin | D40: LBXHGB | E40: g/dL | F40: D10 | G40: PIC + NHANES | H40: Male | I40: 15 | J40: 18 | K40: 13.3 | L40: TRUE | M40: 16.9 | N40: TRUE | O40: x >= 13.3 AND x <= 16.9 | P40: x < 13.3 OR x > 16.9 | Q40: S05 | R40: https://www.mayocliniclabs.com/test-catalog/Overview/801417
...

Sheet Rule_Sources
A1: Source ID | B1: Publisher | C1: Resource | D1: URL | E1: Used for
A2: S01 | B2: Mayo Clinic Laboratories | C2: Basic Metabolic Panel, Serum | D2: https://www.mayocliniclabs.com/test-catalog/overview/113630 | E2: Sodium, potassium, chloride, bicarbonate, BUN, creatinine, calcium, glucose
A3: S02 | B3: Mayo Clinic Laboratories | C3: Magnesium, Serum | D3: https://www.mayocliniclabs.com/test-catalog/overview/8448 | E3: Age-specific magnesium reference intervals
A4: S03 | B4: Mayo Clinic Laboratories | C4: Phosphorus (Inorganic), Serum | D4: https://www.mayocliniclabs.com/test-catalog/Overview/8408 | E4: Age- and sex-specific phosphorus reference intervals
A5: S04 | B5: Mayo Clinic Laboratories | C5: Renal Function Panel, Serum | D5: https://www.mayocliniclabs.com/test-catalog/overview/113634 | E5: Total protein and albumin reference intervals
A6: S05 | B6: Mayo Clinic Laboratories | C6: Hemoglobin, Blood | D6: https://www.mayocliniclabs.com/test-catalog/Overview/801417 | E6: Age- and sex-specific hemoglobin reference intervals
A7: S06 | B7: Mayo Clinic Laboratories | C7: Complete Blood Cell Count with Differential | D7: https://www.mayocliniclabs.com/test-catalog/overview/9109 | E7: Age- and sex-specific platelet reference intervals
A8: S07 | B8: Mayo Clinic Laboratories | C8: Alanine Aminotransferase (ALT), Serum | D8: https://www.mayocliniclabs.com/test-catalog/overview/8362 | E8: Sex-specific ALT reference intervals
A9: S08 | B9: Mayo Clinic Laboratories | C9: Aspartate Aminotransferase (AST), Serum | D9: https://www.mayocliniclabs.com/test-catalog/overview/8360 | E9: Sex-specific AST reference intervals
A10: S09 | B10: Mayo Clinic Laboratories | C10: Alkaline Phosphatase, Serum | D10: https://www.mayocliniclabs.com/test-catalog/Overview/8340 | E10: Age- and sex-specific ALP reference intervals
A11: S10 | B11: Mayo Clinic Laboratories | C11: Gamma-Glutamyltransferase (GGT), Serum | D11: https://www.mayocliniclabs.com/test-catalog/Overview/8677 | E11: Sex-specific adult GGT reference intervals
A12: S11 | B12: Mayo Clinic Laboratories | C12: Bilirubin, Total, Serum | D12: https://www.mayocliniclabs.com/test-catalog/Overview/81785 | E12: Adult total bilirubin reference interval
... A22: S21 | B22: Beckman Coulter | C22: DxH 900/690T public whole-blood reference-range tables | D22: https://www.beckmancoulter.com/download/file/wsr-262438/C06947AC?type=pdf | E22: Prespecified adult CBC percentage/volume ranges for research categorization; not asserted as NHANES-local clinical intervals
